[2021-06-29 13:53:15] ERROR 'SubModules' object has no attribute 'module_name'
[2021-06-29 13:53:15] ERROR Error in Login User
Traceback (most recent call last):
  File "C:\AdventsProduct\V1.0.0\AFS\BusinessModules\ModuleDetails\views.py", line 34, in get_user_rights
    "module_name": m_module.module_name,
AttributeError: 'SubModules' object has no attribute 'module_name'
[2021-06-30 20:17:42] ERROR Object of type Roles is not JSON serializable
[2021-06-30 20:17:42] ERROR Error in Login User
Traceback (most recent call last):
  File "C:\AdventsProduct\V1.0.0\AFS\BusinessModules\ModuleDetails\views.py", line 37, in get_user_rights
    return JsonResponse({"Status": "Success", "modules_list": modules_list, "role_id": role_id})
  File "C:\Users\Administrator\Envs\django\lib\site-packages\django\http\response.py", line 603, in __init__
    data = json.dumps(data, cls=encoder, **json_dumps_params)
  File "c:\users\administrator\appdata\local\programs\python\python38\lib\json\__init__.py", line 234, in dumps
    return cls(
  File "c:\users\administrator\appdata\local\programs\python\python38\lib\json\encoder.py", line 199, in encode
    chunks = self.iterencode(o, _one_shot=True)
  File "c:\users\administrator\appdata\local\programs\python\python38\lib\json\encoder.py", line 257, in iterencode
    return _iterencode(o, 0)
  File "C:\Users\Administrator\Envs\django\lib\site-packages\django\core\serializers\json.py", line 105, in default
    return super().default(o)
  File "c:\users\administrator\appdata\local\programs\python\python38\lib\json\encoder.py", line 179, in default
    raise TypeError(f'Object of type {o.__class__.__name__} '
TypeError: Object of type Roles is not JSON serializable
[2021-06-30 20:17:45] ERROR Object of type Roles is not JSON serializable
[2021-06-30 20:17:45] ERROR Error in Login User
Traceback (most recent call last):
  File "C:\AdventsProduct\V1.0.0\AFS\BusinessModules\ModuleDetails\views.py", line 37, in get_user_rights
    return JsonResponse({"Status": "Success", "modules_list": modules_list, "role_id": role_id})
  File "C:\Users\Administrator\Envs\django\lib\site-packages\django\http\response.py", line 603, in __init__
    data = json.dumps(data, cls=encoder, **json_dumps_params)
  File "c:\users\administrator\appdata\local\programs\python\python38\lib\json\__init__.py", line 234, in dumps
    return cls(
  File "c:\users\administrator\appdata\local\programs\python\python38\lib\json\encoder.py", line 199, in encode
    chunks = self.iterencode(o, _one_shot=True)
  File "c:\users\administrator\appdata\local\programs\python\python38\lib\json\encoder.py", line 257, in iterencode
    return _iterencode(o, 0)
  File "C:\Users\Administrator\Envs\django\lib\site-packages\django\core\serializers\json.py", line 105, in default
    return super().default(o)
  File "c:\users\administrator\appdata\local\programs\python\python38\lib\json\encoder.py", line 179, in default
    raise TypeError(f'Object of type {o.__class__.__name__} '
TypeError: Object of type Roles is not JSON serializable
[2021-06-30 20:17:47] ERROR Object of type Roles is not JSON serializable
[2021-06-30 20:17:47] ERROR Error in Login User
Traceback (most recent call last):
  File "C:\AdventsProduct\V1.0.0\AFS\BusinessModules\ModuleDetails\views.py", line 37, in get_user_rights
    return JsonResponse({"Status": "Success", "modules_list": modules_list, "role_id": role_id})
  File "C:\Users\Administrator\Envs\django\lib\site-packages\django\http\response.py", line 603, in __init__
    data = json.dumps(data, cls=encoder, **json_dumps_params)
  File "c:\users\administrator\appdata\local\programs\python\python38\lib\json\__init__.py", line 234, in dumps
    return cls(
  File "c:\users\administrator\appdata\local\programs\python\python38\lib\json\encoder.py", line 199, in encode
    chunks = self.iterencode(o, _one_shot=True)
  File "c:\users\administrator\appdata\local\programs\python\python38\lib\json\encoder.py", line 257, in iterencode
    return _iterencode(o, 0)
  File "C:\Users\Administrator\Envs\django\lib\site-packages\django\core\serializers\json.py", line 105, in default
    return super().default(o)
  File "c:\users\administrator\appdata\local\programs\python\python38\lib\json\encoder.py", line 179, in default
    raise TypeError(f'Object of type {o.__class__.__name__} '
TypeError: Object of type Roles is not JSON serializable
[2021-06-30 20:48:53] ERROR Cannot resolve keyword 'module' into field. Choices are: created_by, created_date, department, department_id, entities, entities_id, groups, groups_id, id, is_active, modified_by, modified_date, role, role_id, sub_model, sub_model_id, sub_modules, sub_modules_id, tenants, tenants_id
[2021-06-30 20:48:53] ERROR Error in Getting User Credentials
Traceback (most recent call last):
  File "C:\AdventsProduct\V1.0.0\AFS\BusinessModules\ModuleDetails\views.py", line 167, in get_user_credentials
    user_role = UserRoles.objects.filter(role_id = role_id, is_active = True,module=main_module_id)
  File "C:\Users\Administrator\Envs\django\lib\site-packages\django\db\models\manager.py", line 85, in manager_method
    return getattr(self.get_queryset(), name)(*args, **kwargs)
  File "C:\Users\Administrator\Envs\django\lib\site-packages\django\db\models\query.py", line 941, in filter
    return self._filter_or_exclude(False, args, kwargs)
  File "C:\Users\Administrator\Envs\django\lib\site-packages\django\db\models\query.py", line 961, in _filter_or_exclude
    clone._filter_or_exclude_inplace(negate, args, kwargs)
  File "C:\Users\Administrator\Envs\django\lib\site-packages\django\db\models\query.py", line 968, in _filter_or_exclude_inplace
    self._query.add_q(Q(*args, **kwargs))
  File "C:\Users\Administrator\Envs\django\lib\site-packages\django\db\models\sql\query.py", line 1396, in add_q
    clause, _ = self._add_q(q_object, self.used_aliases)
  File "C:\Users\Administrator\Envs\django\lib\site-packages\django\db\models\sql\query.py", line 1415, in _add_q
    child_clause, needed_inner = self.build_filter(
  File "C:\Users\Administrator\Envs\django\lib\site-packages\django\db\models\sql\query.py", line 1289, in build_filter
    lookups, parts, reffed_expression = self.solve_lookup_type(arg)
  File "C:\Users\Administrator\Envs\django\lib\site-packages\django\db\models\sql\query.py", line 1115, in solve_lookup_type
    _, field, _, lookup_parts = self.names_to_path(lookup_splitted, self.get_meta())
  File "C:\Users\Administrator\Envs\django\lib\site-packages\django\db\models\sql\query.py", line 1542, in names_to_path
    raise FieldError("Cannot resolve keyword '%s' into field. "
django.core.exceptions.FieldError: Cannot resolve keyword 'module' into field. Choices are: created_by, created_date, department, department_id, entities, entities_id, groups, groups_id, id, is_active, modified_by, modified_date, role, role_id, sub_model, sub_model_id, sub_modules, sub_modules_id, tenants, tenants_id
[2021-06-30 20:50:26] ERROR 'UserRoles' object has no attribute 'module_id'
[2021-06-30 20:50:26] ERROR Error in Getting User Credentials
Traceback (most recent call last):
  File "C:\AdventsProduct\V1.0.0\AFS\BusinessModules\ModuleDetails\views.py", line 179, in get_user_credentials
    module_ids.append(role.module_id)
AttributeError: 'UserRoles' object has no attribute 'module_id'
[2021-07-03 12:20:02] ERROR Field 'id' expected a number but got ''.
[2021-07-03 12:20:02] ERROR Error in Login User
Traceback (most recent call last):
  File "C:\Users\Administrator\Envs\django\lib\site-packages\django\db\models\fields\__init__.py", line 1823, in get_prep_value
    return int(value)
ValueError: invalid literal for int() with base 10: ''

The above exception was the direct cause of the following exception:

Traceback (most recent call last):
  File "C:\AdventsProduct\V1.0.0\AFS\BusinessModules\ModuleDetails\views.py", line 29, in get_user_rights
    modules_id_list=UserRoles.objects.filter(role=role_id).order_by().values_list('sub_modules').distinct()
  File "C:\Users\Administrator\Envs\django\lib\site-packages\django\db\models\manager.py", line 85, in manager_method
    return getattr(self.get_queryset(), name)(*args, **kwargs)
  File "C:\Users\Administrator\Envs\django\lib\site-packages\django\db\models\query.py", line 941, in filter
    return self._filter_or_exclude(False, args, kwargs)
  File "C:\Users\Administrator\Envs\django\lib\site-packages\django\db\models\query.py", line 961, in _filter_or_exclude
    clone._filter_or_exclude_inplace(negate, args, kwargs)
  File "C:\Users\Administrator\Envs\django\lib\site-packages\django\db\models\query.py", line 968, in _filter_or_exclude_inplace
    self._query.add_q(Q(*args, **kwargs))
  File "C:\Users\Administrator\Envs\django\lib\site-packages\django\db\models\sql\query.py", line 1396, in add_q
    clause, _ = self._add_q(q_object, self.used_aliases)
  File "C:\Users\Administrator\Envs\django\lib\site-packages\django\db\models\sql\query.py", line 1415, in _add_q
    child_clause, needed_inner = self.build_filter(
  File "C:\Users\Administrator\Envs\django\lib\site-packages\django\db\models\sql\query.py", line 1350, in build_filter
    condition = self.build_lookup(lookups, col, value)
  File "C:\Users\Administrator\Envs\django\lib\site-packages\django\db\models\sql\query.py", line 1196, in build_lookup
    lookup = lookup_class(lhs, rhs)
  File "C:\Users\Administrator\Envs\django\lib\site-packages\django\db\models\lookups.py", line 25, in __init__
    self.rhs = self.get_prep_lookup()
  File "C:\Users\Administrator\Envs\django\lib\site-packages\django\db\models\fields\related_lookups.py", line 117, in get_prep_lookup
    self.rhs = target_field.get_prep_value(self.rhs)
  File "C:\Users\Administrator\Envs\django\lib\site-packages\django\db\models\fields\__init__.py", line 1825, in get_prep_value
    raise e.__class__(
ValueError: Field 'id' expected a number but got ''.
[2021-07-05 11:32:23] ERROR Field 'id' expected a number but got ''.
[2021-07-05 11:32:23] ERROR Error in Login User
Traceback (most recent call last):
  File "C:\Users\Administrator\Envs\django\lib\site-packages\django\db\models\fields\__init__.py", line 1823, in get_prep_value
    return int(value)
ValueError: invalid literal for int() with base 10: ''

The above exception was the direct cause of the following exception:

Traceback (most recent call last):
  File "C:\AdventsProduct\V1.0.0\AFS\BusinessModules\ModuleDetails\views.py", line 29, in get_user_rights
    modules_id_list=UserRoles.objects.filter(role=role_id).order_by().values_list('sub_modules').distinct()
  File "C:\Users\Administrator\Envs\django\lib\site-packages\django\db\models\manager.py", line 85, in manager_method
    return getattr(self.get_queryset(), name)(*args, **kwargs)
  File "C:\Users\Administrator\Envs\django\lib\site-packages\django\db\models\query.py", line 941, in filter
    return self._filter_or_exclude(False, args, kwargs)
  File "C:\Users\Administrator\Envs\django\lib\site-packages\django\db\models\query.py", line 961, in _filter_or_exclude
    clone._filter_or_exclude_inplace(negate, args, kwargs)
  File "C:\Users\Administrator\Envs\django\lib\site-packages\django\db\models\query.py", line 968, in _filter_or_exclude_inplace
    self._query.add_q(Q(*args, **kwargs))
  File "C:\Users\Administrator\Envs\django\lib\site-packages\django\db\models\sql\query.py", line 1396, in add_q
    clause, _ = self._add_q(q_object, self.used_aliases)
  File "C:\Users\Administrator\Envs\django\lib\site-packages\django\db\models\sql\query.py", line 1415, in _add_q
    child_clause, needed_inner = self.build_filter(
  File "C:\Users\Administrator\Envs\django\lib\site-packages\django\db\models\sql\query.py", line 1350, in build_filter
    condition = self.build_lookup(lookups, col, value)
  File "C:\Users\Administrator\Envs\django\lib\site-packages\django\db\models\sql\query.py", line 1196, in build_lookup
    lookup = lookup_class(lhs, rhs)
  File "C:\Users\Administrator\Envs\django\lib\site-packages\django\db\models\lookups.py", line 25, in __init__
    self.rhs = self.get_prep_lookup()
  File "C:\Users\Administrator\Envs\django\lib\site-packages\django\db\models\fields\related_lookups.py", line 117, in get_prep_lookup
    self.rhs = target_field.get_prep_value(self.rhs)
  File "C:\Users\Administrator\Envs\django\lib\site-packages\django\db\models\fields\__init__.py", line 1825, in get_prep_value
    raise e.__class__(
ValueError: Field 'id' expected a number but got ''.
[2021-07-27 22:37:07] ERROR local variable 'm_processing_layer_id' referenced before assignment
[2021-07-27 22:37:08] ERROR Error in Getting User Credentials
Traceback (most recent call last):
  File "G:\AdventsProduct\V1.0.0\AFS\BusinessModules\ModuleDetails\views.py", line 394, in get_user_credentials
    "m_processing_layer_id": m_processing_layer_id,
UnboundLocalError: local variable 'm_processing_layer_id' referenced before assignment
[2021-07-27 22:37:09] ERROR local variable 'm_processing_layer_id' referenced before assignment
[2021-07-27 22:37:09] ERROR Error in Getting User Credentials
Traceback (most recent call last):
  File "G:\AdventsProduct\V1.0.0\AFS\BusinessModules\ModuleDetails\views.py", line 394, in get_user_credentials
    "m_processing_layer_id": m_processing_layer_id,
UnboundLocalError: local variable 'm_processing_layer_id' referenced before assignment
[2021-07-27 22:37:20] ERROR local variable 'm_processing_layer_id' referenced before assignment
[2021-07-27 22:37:20] ERROR Error in Getting User Credentials
Traceback (most recent call last):
  File "G:\AdventsProduct\V1.0.0\AFS\BusinessModules\ModuleDetails\views.py", line 394, in get_user_credentials
    "m_processing_layer_id": m_processing_layer_id,
UnboundLocalError: local variable 'm_processing_layer_id' referenced before assignment
[2021-08-01 17:27:53] ERROR local variable 'm_processing_layer_id' referenced before assignment
[2021-08-01 17:27:54] ERROR Error in Getting User Credentials
Traceback (most recent call last):
  File "G:\AdventsProduct\V1.0.0\AFS\BusinessModules\ModuleDetails\views.py", line 483, in get_user_credentials
    "m_processing_layer_id": m_processing_layer_id,
UnboundLocalError: local variable 'm_processing_layer_id' referenced before assignment
[2021-08-01 17:27:55] ERROR local variable 'm_processing_layer_id' referenced before assignment
[2021-08-01 17:27:55] ERROR Error in Getting User Credentials
Traceback (most recent call last):
  File "G:\AdventsProduct\V1.0.0\AFS\BusinessModules\ModuleDetails\views.py", line 483, in get_user_credentials
    "m_processing_layer_id": m_processing_layer_id,
UnboundLocalError: local variable 'm_processing_layer_id' referenced before assignment
[2021-08-01 17:27:57] ERROR local variable 'm_processing_layer_id' referenced before assignment
[2021-08-01 17:27:57] ERROR Error in Getting User Credentials
Traceback (most recent call last):
  File "G:\AdventsProduct\V1.0.0\AFS\BusinessModules\ModuleDetails\views.py", line 483, in get_user_credentials
    "m_processing_layer_id": m_processing_layer_id,
UnboundLocalError: local variable 'm_processing_layer_id' referenced before assignment
[2021-08-01 17:27:58] ERROR local variable 'm_processing_layer_id' referenced before assignment
[2021-08-01 17:27:58] ERROR Error in Getting User Credentials
Traceback (most recent call last):
  File "G:\AdventsProduct\V1.0.0\AFS\BusinessModules\ModuleDetails\views.py", line 483, in get_user_credentials
    "m_processing_layer_id": m_processing_layer_id,
UnboundLocalError: local variable 'm_processing_layer_id' referenced before assignment
[2021-08-01 17:27:59] ERROR local variable 'm_processing_layer_id' referenced before assignment
[2021-08-01 17:27:59] ERROR Error in Getting User Credentials
Traceback (most recent call last):
  File "G:\AdventsProduct\V1.0.0\AFS\BusinessModules\ModuleDetails\views.py", line 483, in get_user_credentials
    "m_processing_layer_id": m_processing_layer_id,
UnboundLocalError: local variable 'm_processing_layer_id' referenced before assignment
[2021-08-01 17:28:00] ERROR local variable 'm_processing_layer_id' referenced before assignment
[2021-08-01 17:28:00] ERROR Error in Getting User Credentials
Traceback (most recent call last):
  File "G:\AdventsProduct\V1.0.0\AFS\BusinessModules\ModuleDetails\views.py", line 483, in get_user_credentials
    "m_processing_layer_id": m_processing_layer_id,
UnboundLocalError: local variable 'm_processing_layer_id' referenced before assignment
[2021-08-01 17:28:00] ERROR local variable 'm_processing_layer_id' referenced before assignment
[2021-08-01 17:28:00] ERROR Error in Getting User Credentials
Traceback (most recent call last):
  File "G:\AdventsProduct\V1.0.0\AFS\BusinessModules\ModuleDetails\views.py", line 483, in get_user_credentials
    "m_processing_layer_id": m_processing_layer_id,
UnboundLocalError: local variable 'm_processing_layer_id' referenced before assignment
[2021-08-01 17:28:01] ERROR local variable 'm_processing_layer_id' referenced before assignment
[2021-08-01 17:28:01] ERROR Error in Getting User Credentials
Traceback (most recent call last):
  File "G:\AdventsProduct\V1.0.0\AFS\BusinessModules\ModuleDetails\views.py", line 483, in get_user_credentials
    "m_processing_layer_id": m_processing_layer_id,
UnboundLocalError: local variable 'm_processing_layer_id' referenced before assignment
[2021-08-03 16:20:21] ERROR local variable 'm_processing_layer_id' referenced before assignment
[2021-08-03 16:20:21] ERROR Error in Getting User Credentials
Traceback (most recent call last):
  File "G:\AdventsProduct\V1.0.0\AFS\BusinessModules\ModuleDetails\views.py", line 483, in get_user_credentials
    "m_processing_layer_id": m_processing_layer_id,
UnboundLocalError: local variable 'm_processing_layer_id' referenced before assignment
[2021-08-03 16:55:34] ERROR local variable 'm_processing_layer_id' referenced before assignment
[2021-08-03 16:55:34] ERROR Error in Getting User Credentials
Traceback (most recent call last):
  File "G:\AdventsProduct\V1.0.0\AFS\BusinessModules\ModuleDetails\views.py", line 483, in get_user_credentials
    "m_processing_layer_id": m_processing_layer_id,
UnboundLocalError: local variable 'm_processing_layer_id' referenced before assignment
[2021-08-03 16:55:35] ERROR local variable 'm_processing_layer_id' referenced before assignment
[2021-08-03 16:55:35] ERROR Error in Getting User Credentials
Traceback (most recent call last):
  File "G:\AdventsProduct\V1.0.0\AFS\BusinessModules\ModuleDetails\views.py", line 483, in get_user_credentials
    "m_processing_layer_id": m_processing_layer_id,
UnboundLocalError: local variable 'm_processing_layer_id' referenced before assignment
[2021-08-03 16:55:36] ERROR local variable 'm_processing_layer_id' referenced before assignment
[2021-08-03 16:55:36] ERROR Error in Getting User Credentials
Traceback (most recent call last):
  File "G:\AdventsProduct\V1.0.0\AFS\BusinessModules\ModuleDetails\views.py", line 483, in get_user_credentials
    "m_processing_layer_id": m_processing_layer_id,
UnboundLocalError: local variable 'm_processing_layer_id' referenced before assignment
[2021-08-10 21:56:37] ERROR local variable 'm_processing_layer_id' referenced before assignment
[2021-08-10 21:56:37] ERROR Error in Getting User Credentials
Traceback (most recent call last):
  File "G:\AdventsProduct\V1.0.0\AFS\BusinessModules\ModuleDetails\views.py", line 483, in get_user_credentials
    "m_processing_layer_id": m_processing_layer_id,
UnboundLocalError: local variable 'm_processing_layer_id' referenced before assignment
[2021-08-10 21:56:38] ERROR local variable 'm_processing_layer_id' referenced before assignment
[2021-08-10 21:56:38] ERROR Error in Getting User Credentials
Traceback (most recent call last):
  File "G:\AdventsProduct\V1.0.0\AFS\BusinessModules\ModuleDetails\views.py", line 483, in get_user_credentials
    "m_processing_layer_id": m_processing_layer_id,
UnboundLocalError: local variable 'm_processing_layer_id' referenced before assignment
[2021-08-10 21:56:40] ERROR local variable 'm_processing_layer_id' referenced before assignment
[2021-08-10 21:56:40] ERROR Error in Getting User Credentials
Traceback (most recent call last):
  File "G:\AdventsProduct\V1.0.0\AFS\BusinessModules\ModuleDetails\views.py", line 483, in get_user_credentials
    "m_processing_layer_id": m_processing_layer_id,
UnboundLocalError: local variable 'm_processing_layer_id' referenced before assignment
[2021-08-10 21:56:40] ERROR local variable 'm_processing_layer_id' referenced before assignment
[2021-08-10 21:56:40] ERROR Error in Getting User Credentials
Traceback (most recent call last):
  File "G:\AdventsProduct\V1.0.0\AFS\BusinessModules\ModuleDetails\views.py", line 483, in get_user_credentials
    "m_processing_layer_id": m_processing_layer_id,
UnboundLocalError: local variable 'm_processing_layer_id' referenced before assignment
[2021-08-10 21:56:42] ERROR local variable 'm_processing_layer_id' referenced before assignment
[2021-08-10 21:56:42] ERROR Error in Getting User Credentials
Traceback (most recent call last):
  File "G:\AdventsProduct\V1.0.0\AFS\BusinessModules\ModuleDetails\views.py", line 483, in get_user_credentials
    "m_processing_layer_id": m_processing_layer_id,
UnboundLocalError: local variable 'm_processing_layer_id' referenced before assignment
[2021-08-10 22:04:42] ERROR local variable 'm_processing_layer_id' referenced before assignment
[2021-08-10 22:04:42] ERROR Error in Getting User Credentials
Traceback (most recent call last):
  File "G:\AdventsProduct\V1.0.0\AFS\BusinessModules\ModuleDetails\views.py", line 483, in get_user_credentials
    "m_processing_layer_id": m_processing_layer_id,
UnboundLocalError: local variable 'm_processing_layer_id' referenced before assignment
[2021-08-10 22:04:42] ERROR local variable 'm_processing_layer_id' referenced before assignment
[2021-08-10 22:04:42] ERROR Error in Getting User Credentials
Traceback (most recent call last):
  File "G:\AdventsProduct\V1.0.0\AFS\BusinessModules\ModuleDetails\views.py", line 483, in get_user_credentials
    "m_processing_layer_id": m_processing_layer_id,
UnboundLocalError: local variable 'm_processing_layer_id' referenced before assignment
[2021-08-10 22:04:43] ERROR local variable 'm_processing_layer_id' referenced before assignment
[2021-08-10 22:04:43] ERROR Error in Getting User Credentials
Traceback (most recent call last):
  File "G:\AdventsProduct\V1.0.0\AFS\BusinessModules\ModuleDetails\views.py", line 483, in get_user_credentials
    "m_processing_layer_id": m_processing_layer_id,
UnboundLocalError: local variable 'm_processing_layer_id' referenced before assignment
[2021-08-10 22:04:43] ERROR local variable 'm_processing_layer_id' referenced before assignment
[2021-08-10 22:04:43] ERROR Error in Getting User Credentials
Traceback (most recent call last):
  File "G:\AdventsProduct\V1.0.0\AFS\BusinessModules\ModuleDetails\views.py", line 483, in get_user_credentials
    "m_processing_layer_id": m_processing_layer_id,
UnboundLocalError: local variable 'm_processing_layer_id' referenced before assignment
[2021-08-10 22:04:43] ERROR local variable 'm_processing_layer_id' referenced before assignment
[2021-08-10 22:04:43] ERROR Error in Getting User Credentials
Traceback (most recent call last):
  File "G:\AdventsProduct\V1.0.0\AFS\BusinessModules\ModuleDetails\views.py", line 483, in get_user_credentials
    "m_processing_layer_id": m_processing_layer_id,
UnboundLocalError: local variable 'm_processing_layer_id' referenced before assignment
[2021-08-10 22:04:43] ERROR local variable 'm_processing_layer_id' referenced before assignment
[2021-08-10 22:04:43] ERROR Error in Getting User Credentials
Traceback (most recent call last):
  File "G:\AdventsProduct\V1.0.0\AFS\BusinessModules\ModuleDetails\views.py", line 483, in get_user_credentials
    "m_processing_layer_id": m_processing_layer_id,
UnboundLocalError: local variable 'm_processing_layer_id' referenced before assignment
[2021-08-24 21:38:36] ERROR local variable 'm_processing_layer_id' referenced before assignment
[2021-08-24 21:38:36] ERROR Error in Getting User Credentials
Traceback (most recent call last):
  File "G:\AdventsProduct\V1.0.0\AFS\BusinessModules\ModuleDetails\views.py", line 483, in get_user_credentials
    "m_processing_layer_id": m_processing_layer_id,
UnboundLocalError: local variable 'm_processing_layer_id' referenced before assignment
[2021-08-24 21:38:38] ERROR local variable 'm_processing_layer_id' referenced before assignment
[2021-08-24 21:38:38] ERROR Error in Getting User Credentials
Traceback (most recent call last):
  File "G:\AdventsProduct\V1.0.0\AFS\BusinessModules\ModuleDetails\views.py", line 483, in get_user_credentials
    "m_processing_layer_id": m_processing_layer_id,
UnboundLocalError: local variable 'm_processing_layer_id' referenced before assignment
[2021-08-24 21:38:39] ERROR local variable 'm_processing_layer_id' referenced before assignment
[2021-08-24 21:38:39] ERROR Error in Getting User Credentials
Traceback (most recent call last):
  File "G:\AdventsProduct\V1.0.0\AFS\BusinessModules\ModuleDetails\views.py", line 483, in get_user_credentials
    "m_processing_layer_id": m_processing_layer_id,
UnboundLocalError: local variable 'm_processing_layer_id' referenced before assignment
[2021-08-24 21:38:39] ERROR local variable 'm_processing_layer_id' referenced before assignment
[2021-08-24 21:38:39] ERROR Error in Getting User Credentials
Traceback (most recent call last):
  File "G:\AdventsProduct\V1.0.0\AFS\BusinessModules\ModuleDetails\views.py", line 483, in get_user_credentials
    "m_processing_layer_id": m_processing_layer_id,
UnboundLocalError: local variable 'm_processing_layer_id' referenced before assignment
[2021-08-24 21:38:39] ERROR local variable 'm_processing_layer_id' referenced before assignment
[2021-08-24 21:38:39] ERROR Error in Getting User Credentials
Traceback (most recent call last):
  File "G:\AdventsProduct\V1.0.0\AFS\BusinessModules\ModuleDetails\views.py", line 483, in get_user_credentials
    "m_processing_layer_id": m_processing_layer_id,
UnboundLocalError: local variable 'm_processing_layer_id' referenced before assignment
[2021-08-24 21:38:40] ERROR local variable 'm_processing_layer_id' referenced before assignment
[2021-08-24 21:38:40] ERROR Error in Getting User Credentials
Traceback (most recent call last):
  File "G:\AdventsProduct\V1.0.0\AFS\BusinessModules\ModuleDetails\views.py", line 483, in get_user_credentials
    "m_processing_layer_id": m_processing_layer_id,
UnboundLocalError: local variable 'm_processing_layer_id' referenced before assignment
[2021-08-24 21:38:40] ERROR local variable 'm_processing_layer_id' referenced before assignment
[2021-08-24 21:38:40] ERROR Error in Getting User Credentials
Traceback (most recent call last):
  File "G:\AdventsProduct\V1.0.0\AFS\BusinessModules\ModuleDetails\views.py", line 483, in get_user_credentials
    "m_processing_layer_id": m_processing_layer_id,
UnboundLocalError: local variable 'm_processing_layer_id' referenced before assignment
[2021-08-24 21:38:40] ERROR local variable 'm_processing_layer_id' referenced before assignment
[2021-08-24 21:38:40] ERROR Error in Getting User Credentials
Traceback (most recent call last):
  File "G:\AdventsProduct\V1.0.0\AFS\BusinessModules\ModuleDetails\views.py", line 483, in get_user_credentials
    "m_processing_layer_id": m_processing_layer_id,
UnboundLocalError: local variable 'm_processing_layer_id' referenced before assignment
[2021-08-24 21:38:40] ERROR local variable 'm_processing_layer_id' referenced before assignment
[2021-08-24 21:38:40] ERROR Error in Getting User Credentials
Traceback (most recent call last):
  File "G:\AdventsProduct\V1.0.0\AFS\BusinessModules\ModuleDetails\views.py", line 483, in get_user_credentials
    "m_processing_layer_id": m_processing_layer_id,
UnboundLocalError: local variable 'm_processing_layer_id' referenced before assignment
[2021-08-24 21:38:40] ERROR local variable 'm_processing_layer_id' referenced before assignment
[2021-08-24 21:38:40] ERROR Error in Getting User Credentials
Traceback (most recent call last):
  File "G:\AdventsProduct\V1.0.0\AFS\BusinessModules\ModuleDetails\views.py", line 483, in get_user_credentials
    "m_processing_layer_id": m_processing_layer_id,
UnboundLocalError: local variable 'm_processing_layer_id' referenced before assignment
[2021-08-24 21:38:41] ERROR local variable 'm_processing_layer_id' referenced before assignment
[2021-08-24 21:38:41] ERROR Error in Getting User Credentials
Traceback (most recent call last):
  File "G:\AdventsProduct\V1.0.0\AFS\BusinessModules\ModuleDetails\views.py", line 483, in get_user_credentials
    "m_processing_layer_id": m_processing_layer_id,
UnboundLocalError: local variable 'm_processing_layer_id' referenced before assignment
[2021-08-24 21:38:41] ERROR local variable 'm_processing_layer_id' referenced before assignment
[2021-08-24 21:38:41] ERROR Error in Getting User Credentials
Traceback (most recent call last):
  File "G:\AdventsProduct\V1.0.0\AFS\BusinessModules\ModuleDetails\views.py", line 483, in get_user_credentials
    "m_processing_layer_id": m_processing_layer_id,
UnboundLocalError: local variable 'm_processing_layer_id' referenced before assignment
[2021-08-24 21:38:41] ERROR local variable 'm_processing_layer_id' referenced before assignment
[2021-08-24 21:38:41] ERROR Error in Getting User Credentials
Traceback (most recent call last):
  File "G:\AdventsProduct\V1.0.0\AFS\BusinessModules\ModuleDetails\views.py", line 483, in get_user_credentials
    "m_processing_layer_id": m_processing_layer_id,
UnboundLocalError: local variable 'm_processing_layer_id' referenced before assignment
[2021-08-24 21:38:45] ERROR local variable 'm_processing_layer_id' referenced before assignment
[2021-08-24 21:38:45] ERROR Error in Getting User Credentials
Traceback (most recent call last):
  File "G:\AdventsProduct\V1.0.0\AFS\BusinessModules\ModuleDetails\views.py", line 483, in get_user_credentials
    "m_processing_layer_id": m_processing_layer_id,
UnboundLocalError: local variable 'm_processing_layer_id' referenced before assignment
[2021-08-26 10:47:16] ERROR local variable 'm_processing_layer_id' referenced before assignment
[2021-08-26 10:47:16] ERROR Error in Getting User Credentials
Traceback (most recent call last):
  File "G:\AdventsProduct\V1.0.0\AFS\BusinessModules\ModuleDetails\views.py", line 483, in get_user_credentials
    "m_processing_layer_id": m_processing_layer_id,
UnboundLocalError: local variable 'm_processing_layer_id' referenced before assignment
[2021-09-30 17:11:54] ERROR local variable 'm_processing_layer_id' referenced before assignment
[2021-09-30 17:11:54] ERROR Error in Getting User Credentials
Traceback (most recent call last):
  File "G:\AdventsProduct\V1.0.0\AFS\BusinessModules\ModuleDetails\views.py", line 483, in get_user_credentials
    "m_processing_layer_id": m_processing_layer_id,
UnboundLocalError: local variable 'm_processing_layer_id' referenced before assignment
[2021-09-30 17:11:56] ERROR local variable 'm_processing_layer_id' referenced before assignment
[2021-09-30 17:11:56] ERROR Error in Getting User Credentials
Traceback (most recent call last):
  File "G:\AdventsProduct\V1.0.0\AFS\BusinessModules\ModuleDetails\views.py", line 483, in get_user_credentials
    "m_processing_layer_id": m_processing_layer_id,
UnboundLocalError: local variable 'm_processing_layer_id' referenced before assignment
[2021-11-12 09:06:28] ERROR local variable 'm_processing_layer_id' referenced before assignment
[2021-11-12 09:06:28] ERROR Error in Getting User Credentials
Traceback (most recent call last):
  File "G:\AdventsProduct\V1.0.0\AFS\BusinessModules\ModuleDetails\views.py", line 483, in get_user_credentials
    "m_processing_layer_id": m_processing_layer_id,
UnboundLocalError: local variable 'm_processing_layer_id' referenced before assignment
[2021-11-12 09:06:39] ERROR local variable 'm_processing_layer_id' referenced before assignment
[2021-11-12 09:06:39] ERROR Error in Getting User Credentials
Traceback (most recent call last):
  File "G:\AdventsProduct\V1.0.0\AFS\BusinessModules\ModuleDetails\views.py", line 483, in get_user_credentials
    "m_processing_layer_id": m_processing_layer_id,
UnboundLocalError: local variable 'm_processing_layer_id' referenced before assignment
[2021-11-12 09:06:55] ERROR local variable 'm_processing_layer_id' referenced before assignment
[2021-11-12 09:06:55] ERROR Error in Getting User Credentials
Traceback (most recent call last):
  File "G:\AdventsProduct\V1.0.0\AFS\BusinessModules\ModuleDetails\views.py", line 483, in get_user_credentials
    "m_processing_layer_id": m_processing_layer_id,
UnboundLocalError: local variable 'm_processing_layer_id' referenced before assignment
[2021-11-12 09:06:57] ERROR local variable 'm_processing_layer_id' referenced before assignment
[2021-11-12 09:06:57] ERROR Error in Getting User Credentials
Traceback (most recent call last):
  File "G:\AdventsProduct\V1.0.0\AFS\BusinessModules\ModuleDetails\views.py", line 483, in get_user_credentials
    "m_processing_layer_id": m_processing_layer_id,
UnboundLocalError: local variable 'm_processing_layer_id' referenced before assignment
[2021-11-12 09:06:59] ERROR local variable 'm_processing_layer_id' referenced before assignment
[2021-11-12 09:06:59] ERROR Error in Getting User Credentials
Traceback (most recent call last):
  File "G:\AdventsProduct\V1.0.0\AFS\BusinessModules\ModuleDetails\views.py", line 483, in get_user_credentials
    "m_processing_layer_id": m_processing_layer_id,
UnboundLocalError: local variable 'm_processing_layer_id' referenced before assignment
[2021-12-09 04:30:57] ERROR Field 'id' expected a number but got ''.
[2021-12-09 04:30:57] ERROR Error in Login User
Traceback (most recent call last):
  File "C:\Users\user\Envs\django\lib\site-packages\django\db\models\fields\__init__.py", line 1774, in get_prep_value
    return int(value)
ValueError: invalid literal for int() with base 10: ''

The above exception was the direct cause of the following exception:

Traceback (most recent call last):
  File "G:\AdventsProduct\V1.0.0\AFS\BusinessModules\ModuleDetails\views.py", line 29, in get_user_rights
    modules_id_list=UserRoles.objects.filter(role=role_id).order_by().values_list('sub_modules').distinct()
  File "C:\Users\user\Envs\django\lib\site-packages\django\db\models\manager.py", line 85, in manager_method
    return getattr(self.get_queryset(), name)(*args, **kwargs)
  File "C:\Users\user\Envs\django\lib\site-packages\django\db\models\query.py", line 942, in filter
    return self._filter_or_exclude(False, *args, **kwargs)
  File "C:\Users\user\Envs\django\lib\site-packages\django\db\models\query.py", line 962, in _filter_or_exclude
    clone._filter_or_exclude_inplace(negate, *args, **kwargs)
  File "C:\Users\user\Envs\django\lib\site-packages\django\db\models\query.py", line 969, in _filter_or_exclude_inplace
    self._query.add_q(Q(*args, **kwargs))
  File "C:\Users\user\Envs\django\lib\site-packages\django\db\models\sql\query.py", line 1358, in add_q
    clause, _ = self._add_q(q_object, self.used_aliases)
  File "C:\Users\user\Envs\django\lib\site-packages\django\db\models\sql\query.py", line 1377, in _add_q
    child_clause, needed_inner = self.build_filter(
  File "C:\Users\user\Envs\django\lib\site-packages\django\db\models\sql\query.py", line 1319, in build_filter
    condition = self.build_lookup(lookups, col, value)
  File "C:\Users\user\Envs\django\lib\site-packages\django\db\models\sql\query.py", line 1165, in build_lookup
    lookup = lookup_class(lhs, rhs)
  File "C:\Users\user\Envs\django\lib\site-packages\django\db\models\lookups.py", line 24, in __init__
    self.rhs = self.get_prep_lookup()
  File "C:\Users\user\Envs\django\lib\site-packages\django\db\models\fields\related_lookups.py", line 117, in get_prep_lookup
    self.rhs = target_field.get_prep_value(self.rhs)
  File "C:\Users\user\Envs\django\lib\site-packages\django\db\models\fields\__init__.py", line 1776, in get_prep_value
    raise e.__class__(
ValueError: Field 'id' expected a number but got ''.
[2021-12-09 04:57:08] ERROR (1048, "Column 'login_time' cannot be null")
[2021-12-09 04:57:08] ERROR Error in Logout User
Traceback (most recent call last):
  File "C:\Users\user\Envs\django\lib\site-packages\django\db\backends\mysql\base.py", line 73, in execute
    return self.cursor.execute(query, args)
  File "C:\Users\user\Envs\django\lib\site-packages\MySQLdb\cursors.py", line 206, in execute
    res = self._query(query)
  File "C:\Users\user\Envs\django\lib\site-packages\MySQLdb\cursors.py", line 319, in _query
    db.query(q)
  File "C:\Users\user\Envs\django\lib\site-packages\MySQLdb\connections.py", line 259, in query
    _mysql.connection.query(self, query)
MySQLdb._exceptions.OperationalError: (1048, "Column 'login_time' cannot be null")

During handling of the above exception, another exception occurred:

Traceback (most recent call last):
  File "G:\AdventsProduct\V1.0.0\AFS\BusinessModules\ModuleDetails\views.py", line 126, in get_user_logout
    UserLoginLog.objects.create(
  File "C:\Users\user\Envs\django\lib\site-packages\django\db\models\manager.py", line 85, in manager_method
    return getattr(self.get_queryset(), name)(*args, **kwargs)
  File "C:\Users\user\Envs\django\lib\site-packages\django\db\models\query.py", line 447, in create
    obj.save(force_insert=True, using=self.db)
  File "C:\Users\user\Envs\django\lib\site-packages\django\db\models\base.py", line 753, in save
    self.save_base(using=using, force_insert=force_insert,
  File "C:\Users\user\Envs\django\lib\site-packages\django\db\models\base.py", line 790, in save_base
    updated = self._save_table(
  File "C:\Users\user\Envs\django\lib\site-packages\django\db\models\base.py", line 895, in _save_table
    results = self._do_insert(cls._base_manager, using, fields, returning_fields, raw)
  File "C:\Users\user\Envs\django\lib\site-packages\django\db\models\base.py", line 933, in _do_insert
    return manager._insert(
  File "C:\Users\user\Envs\django\lib\site-packages\django\db\models\manager.py", line 85, in manager_method
    return getattr(self.get_queryset(), name)(*args, **kwargs)
  File "C:\Users\user\Envs\django\lib\site-packages\django\db\models\query.py", line 1254, in _insert
    return query.get_compiler(using=using).execute_sql(returning_fields)
  File "C:\Users\user\Envs\django\lib\site-packages\django\db\models\sql\compiler.py", line 1397, in execute_sql
    cursor.execute(sql, params)
  File "C:\Users\user\Envs\django\lib\site-packages\django\db\backends\utils.py", line 98, in execute
    return super().execute(sql, params)
  File "C:\Users\user\Envs\django\lib\site-packages\django\db\backends\utils.py", line 66, in execute
    return self._execute_with_wrappers(sql, params, many=False, executor=self._execute)
  File "C:\Users\user\Envs\django\lib\site-packages\django\db\backends\utils.py", line 75, in _execute_with_wrappers
    return executor(sql, params, many, context)
  File "C:\Users\user\Envs\django\lib\site-packages\django\db\backends\utils.py", line 84, in _execute
    return self.cursor.execute(sql, params)
  File "C:\Users\user\Envs\django\lib\site-packages\django\db\backends\mysql\base.py", line 78, in execute
    raise IntegrityError(*tuple(e.args))
django.db.utils.IntegrityError: (1048, "Column 'login_time' cannot be null")
